Workbook

Sheet ANTEPROYECTO
B3: PRESUPUESTO DE ANTEPROYECTO
B4: DESCRIPCION | C4: UND | D4: CANTIDAD | E4: VALOR TOTAL
B5: VISITA AL LOTE | C5: GLB | D5: 1 | E5: 500000
B6: ANALISIS DEL ENTORNO | C6: GLB | D6: 1 | E6: 1000000
B7: FORMULACION DE PROYECTO | C7: GLB | D7: 1 | E7: 15000000
B8: ESTUDIOS GEOTECNICOS | C8: GLB | D8: 1 | E8: 3000000
B9: DISEÑO ARQUITECTONICO PROPUESTA GENERAL | C9: GLB | D9: 1 | E9: 80000000
B10: DISEÑOS ESTRUCTURALES Y NO ESTRUCTURALES | C10: GLB | D10: 1 | E10: 30000000
B11: TRAMITE DE LICENCIA | C11: GLB | D11: 1 | E11: 6000000
B12: TRAMITES DE SERVICIO PUBLICO | C12: GLB | D12: 1 | E12: 10000000
D13: VR TOTAL | E13: =SUM(E5:E12) -> 145500000

Sheet PRESUPUESTO
B2: PRESUPUESTO DEL PROYECTO
B4: DESCRIPCIÓN | C4: UND | D4: CANTIDAD | E4: PRECIO UNITARIO | F4: VALOR PARCIAL | G4: VALOR TOTAL
B5: OBRAS PRELIMINARES | G5: =F6+F7+F8 -> 11077693
B6: SUMINISTRO E INSTALACION CERRAMIENTO PROVISIONAL H=2,14 M. EN POLISOMBRA VERDE | C6: ML | D6: =APU!H7 -> 75.55 | E6: =APU!H48 -> 0 | F6: =D6*E6 -> 0
B7: LIMPIEZA, DESCAPOTE, RETIRO SOBRANTES - MECÁNICO H = 0,20 mts | C7: M2 | D7: 1140 | E7: =APU!H96 -> 5841.1343 | F7: =D7*E7 -> 6658893.1
B8: LOCALIZACION Y REPLANTEO TOPOGRAFICO | C8: M2 | D8: 644 | E8: =APU!H192 -> 6861.491 | F8: =D8*E8 -> 4418800.2
B9: DEMOLICION | G9: =F10 -> 51464268
B10: DEMOLICION DE CONSTRUCCION EXISTENTE (INC. RETIRO DE SOBR. | C10: M2 | D10: 491 | E10: =APU!H240 -> 104815.21 | F10: =E10*D10 -> 51464268
B11: EXCAVACIONES, RELLENOS Y REEMPLAZOS | G11: =F12+F13 -> 33144691
B12: EXCAVACION MANUAL EN MATERIAL COMUN (INCLUYE CARGUE Y RETIRO) | C12: M3 | D12: 95 | E12: =APU!H336 -> 89155.292 | F12: =D12*E12 -> 8469752.7
B13: RELLENO EN RECEBO COMUN (SUMINISTRO, EXTENDIDO, HUMEDECIMIENTO Y COMPACTACIÓN) | C13: M3 | D13: 292 | E13: =APU!H384 -> 84503.213 | F13: =D13*E13 -> 24674938
B14: CIMENTACION | G14: =F15+F16+F17+F18+F19 -> 3.7807404e+08
B15: VACIADO DE CONCRETO DE LIMPIEZA 14 MPA (2000 PSI) | C15: M3 | D15: 4.25 | E15: =APU!H432 -> 538803 | F15: =E15*D15 -> 2289912.8
B16: VACIADO DE CONCRETOS PARA ZAPATAS 24MPA (3500 PSI) | C16: M3 | D16: =APU!H439 -> 27.62 | E16: =APU!H480 -> 555170.13 | F16: =E16*D16 -> 15333799
B17: VACIADO DE CONCRETO PARA VIGAS DE CIMENTACIÓN 24MPA (3500 PSI) | C17: M3 | D17: 67.35 | E17: =APU!H528 -> 532493.96 | F17: =E17*D17 -> 35863468
B18: VACIADO DE PLACA CONTRAPISO DE 10 CM EN CONCRETO DE 24MPA (3500 PSI) | C18: M3 | D18: =APU!H535 -> 697.6 | E18: =APU!H574 -> 457567.42 | F18: =E18*D18 -> 3.1919903e+08
B19: IMPERMEABILIZACIÓN CON GEOTEXTIL NT2000 DE PAVCO O SIMILAR | C19: M2 | D19: 697.6 | E19: =APU!H620 -> 7723.384 | F19: =E19*D19 -> 5387832.7
B20: ESTRUCTURA | G20: =F21+F22+F23+F24+F25+F26+F27+F28+F29+F30 -> 5.0168402e+08
B21: COLUMNAS EN CONCRETO DE 24MPA (3500 PSI) | C21: M3 | D21: =APU!H627 -> 15.24 | E21: =APU!H668 -> 668367.12 | F21: =E21*D21 -> 10185915
B22: VIGA DE APOYO ESTRUCTURA METALICA EN CONCRETO DE 24MPA (3500 PSI) | C22: M3 | D22: 1.03 | E22: =APU!H716 -> 1897367.2 | F22: =E22*D22 -> 1954288.2
B23: MURO EN CONCRETO DE 24MPA (3500 PSI) | C23: M3 | D23: =APU!H723 -> 2.48 | E23: =APU!H764 -> 1108729.1 | F23: =E23*D23 -> 2749648.2
B24: LOSA ALIGERADA ENTREPISO H = 50 CM - CONCRETO 24MPA (3500 PSI) | C24: M2 | D24: =APU!H771 -> 488.39 | E24: =APU!H814 -> 477189.84 | F24: =E24*D24 -> 2.3305475e+08
B25: LOSA ALIGERADA CUBIERTA H = 45 CM - CONCRETO 24MPA (3500 PSI) | C25: M2 | D25: =APU!H821 -> 195.19 | E25: =APU!H864 -> 515619.46 | F25: =E25*D25 -> 1.0064376e+08
B26: RAMPA EN CONCRETO AÉREA DE 24MPA (3500 PSI)SEGÚN DISEÑO ESTRUCTURAL | C26: M3 | D26: =APU!H871 -> 7.29 | E26: =APU!H913 -> 728002.5 | F26: =E26*D26 -> 5307138.2
B27: VIGAS AÉREAS EN CONCRETO 24MPA (3500 PSI) | C27: M3 | D27: =APU!H920 -> 20.09 | E27: =APU!H960 -> 563131.51 | F27: =E27*D27 -> 11313312
B28: ESCALERAS EN CONCRETO 24MPA (3500 PSI) | C28: M3 | D28: =APU!H967 -> 6.82 | E28: =APU!H1009 -> 974325.8 | F28: =E28*D28 -> 6644902
B29: TANQUE PARA ALMACENAMIENTO DE AGUA EN CONCRETO IMPERMEABILIZADO DE 28 MPA (4000 PSI) | C29: M3 | D29: 31.5 | E29: =APU!H1059 -> 678569.71 | F29: =E29*D29 -> 21374946
B30: FIGURADO DE ACERO DE 60000 PSI | C30: KG | D30: =APU!H1066 -> 27294.82 | E30: =APU!H1104 -> 3973.4778 | F30: =E30*D30 -> 1.0845536e+08
B31: TOTAL COSTOS DIRECTOS | G31: =G5+G9+G11+G14+G20 -> 9.7544472e+08
E32: ADMINISTRACION | F32: =AIU!D6 -> 0.18844738 | G32: =G31*F32 -> 183820000
B33: TOTAL GLOBAL DEL PROYECTO | E33: IMPREVISTOS | F33: 0.02 | G33: =G31*F33 -> 19508894
B34: COSTO TOTAL DEL PROYECTO | C34: =G37 -> 1.2252048e+09 | E34: UTILIDADES | F34: 0.04 | G34: =G31*F34 -> 39017789
B35: COSTO TOTAL DEL ANTEPROYECTO | C35: =ANTEPROYECTO!E13 -> 145500000 | E35: IVA | F35: 0.19 | G35: =G34*F35 -> 7413379.8
B36: COSTO TOTAL | C36: =SUM(C34:C35) -> 1.3707048e+09 | E36: TOTAL COSTOS INDIRECTOS | G36: =G32+G33+G34+G35 -> 2.4976006e+08
E37: COSTO TOTAL CD+CI | G37: =G31+G36 -> 1.2252048e+09

Sheet AIU
B3: COSTOS TOTAL DIRECTOS | C3: =+PRESUPUESTO!G31 -> 9.7544472e+08
B5: DESCRIPCION | C5: UND | D5: CANTIDAD | E5: MESES | F5: VALOR UNITARIO | G5: PRESTACIONES SOCIALES | H5: SUBTOTAL
B6: ADMINISTRACION | C6: PORCENTAJE | D6: =H17/C3 -> 0.18844738
B7: DIRECTOR DE OBRA | C7: MES | D7: 1 | E7: 4 | F7: 10000000 | G7: 1.6 | H7: =F7*G7*E7 -> 64000000
B8: RESIDENTE | C8: MES | D8: 1 | E8: 4 | F8: 6500000 | G8: 1.6 | H8: =F8*G8*E8 -> 41600000
B9: MAESTRO DE OBRA | C9: MES | D9: 1 | E9: 4 | F9: 4200000 | G9: 1.6 | H9: =F9*G9*E9 -> 26880000
B10: SST | C10: MES | D10: 1 | E10: 4 | F10: 1300000 | G10: 1.6 | H10: =F10*G10*E10 -> 8320000
B11: VIGILANTE | C11: MES | D11: 1 | E11: 4 | F11: 1300000 | G11: 1.6 | H11: =F11*G11*E11 -> 8320000
G12: VALOR PARCIAL | H12: =SUM(H7:H11) -> 149120000
B14: MANTENIMIENTO DE OFICINA | C14: MES | D14: 1 | E14: 4 | F14: 1800000 | G14: - | H14: =F14*E14 -> 7200000
B15: COMITÉ DE OBRAS | C15: MES | D15: 1 | E15: 11 | F15: 2500000 | G15: - | H15: =F15*E15 -> 27500000
G16: VALOR PARCIAL | H16: =H14+H15 -> 34700000
G17: VR TOTAL ADMINISTRACION | H17: =H12+H16 -> 183820000
B19: IMPREVISTOS | C19: PORCENTAJE | D19: =H20/C3 -> 0.02
B20: ESTUDIO DE RIESGO | C20: MES | D20: 1 | E20: 0.02 | F20: - | G20: - | H20: =E20*C3 -> 19508894
B22: UTILIDADES | C22: PORCENTAJE | D22: 0.04
B23: UTILIDADES | C23: - | D23: 1 | E23: 0.04 | F23: - | G23: - | H23: =E23*C3 -> 39017789
B25: IVA | C25: PORCENTAJE | D25: =H26/PRESUPUESTO!G34 -> 0.19
B26: IVA | C26: - | D26: 1 | E26: 0.19 | F26: - | G26: - | H26: =E26*H23 -> 7413379.8
B28: COSTO TOTAL INDIRECTOS | C28: =H17+H20+H23+H26 -> 2.4976006e+08

Sheet APU
B2: ANALISIS DE PRECIO UNITARIO
B4: CAPITULO | D4: OBRAS PRELIMINARES
B5: SUMINISTRO E INSTALACION DE CERRAMIENTO PROVISIONAL H:2,14 M EN POLISOMBRA VERDE
B6: ITEM | G6: UNIDAD | H6: ML
G7: CANTIDAD | H7: 75.55
B8: I- EQUIPOS
B9: DESCRIPCION | E9: UNIDAD | F9: CANT/RENDI | G9: VALOR UNITARIO | H9: VALOR PARCIAL
H10: =F10*G10 -> 0
H11: =F11*G11 -> 0
H12: =F12*G12 -> 0
G13: SUBTOTAL EQUIPOS | H13: =SUM(H10:H12) -> 0
B15: II- MATERIALES
B16: DESCRIPCION | E16: UNIDAD | F16: CANT/RENDI | G16: VALOR UNITARIO | H16: VALOR PARCIAL
B17: VARA DE CLAVO | E17: ML | F17: 1.34 | G17: 1617 | H17: =F17*G17 -> 2166.78
B18: PUNTILLA | E18: LB | F18: 0.05 | G18: 3781 | H18: =F18*G18 -> 189.05
B19: CONCRETO 10MPA (1500 PSI) | E19: M3 | F19: 0.005 | G19: 321369 | H19: =F19*G19 -> 1606.845
B20: POLISOMBRA VERDE | E20: M2 | F20: 2.2 | G20: 1786 | H20: =F20*G20 -> 3929.2
B21: GRAPA 1" | E21: LB | F21: 0.022 | G21: 3392 | H21: =F21*G21 -> 74.624
G22: SUBTOTAL MATERIALES | H22: =SUM(H17:H21) -> 7966.499
B24: III- MANO DE OBRA
B25: DESCRIPCION | E25: UNIDAD | F25: CANT/RENDI | G25: VALOR UNITARIO | H25: VALOR PARCIAL
B26: CUADRILLA ALB 0:2 | E26: DIA | F26: 0.0927 | G26: 77564 | H26: =G26*F26 -> 7190.1828
H27: =F27*G27 -> 0
H29: =F29*G29 -> 0
G30: SUBTOTAL MANO DE OBRA | H30: =SUM(H26:H29) -> 7190.1828
B32: IV- TRANSPORTE
B33: DESCRIPCION | E33: UNIDAD | F33: CANT/RENDI | G33: VALOR UNITARIO | H33: VALOR PARCIAL
H34: =F34*G34 -> 0
H35: =F35*G35 -> 0
H36: =F36*G36 -> 0
G37: SUBTOTAL TRANSPORTE | H37: =SUM(H34:H36) -> 0
B39: V- HERRAMIENTAS
B40: DESCRIPCION | E40: UNIDAD | F40: CANT/RENDI | G40: VALOR UNITARIO | H40: VALOR PARCIAL
B41: HERRAMIENTAS MENORES | E41: - | F41: 5 | G41: 1000 | H41: =G41*F41 -> 5000
H42: =F42*G42 -> 0
H43: =F43*G43 -> 0
H44: =F44*G44 -> 0
G45: SUBTOTAL TRANSPORTE | H45: =SUM(H41:H44) -> 5000
G48: TOTAL COSTOS DIRECTOS
B52: CAPITULO | D52: OBRAS PRELIMINARES
...

Sheet MATERIALES
B2: LISTADO DE MATERIALES
B4: Insumo | C4: U.M. | D4: Vr.Unitario
B5: ACCESORIOS FIJACIÒN TEJA METÀLICA TERMOACÚSTICA | C5: UN | D5: 4727
B6: ABRAZADERAS 1/2" A 2" | C6: UN | D6: 4412
B7: ABRAZADERAS 2" | C7: UN | D7: 6092
B8: ABRAZADERAS 3" | C8: UN | D8: 7143
B9: ABRAZADERAS 4" | C9: UN | D9: 8193
B10: ABRAZADERA DOBLE ALETA | C10: UN | D10: 10706
B11: ABRAZADERA TRAPECIO 1" | C11: UN | D11: 5042
B12: ABRAZADERA TRAPECIO 1-1/4" | C12: UN | D12: 5672
B13: ABRAZADERA TRAPECIO 1-1/2" | C13: UN | D13: 6092
B14: ABRAZADERA TRAPECIO 2-1/2" | C14: UN | D14: 7143
B15: ABRAZADERA TRAPECIO 3" | C15: UN | D15: 7983
B16: ABUTILON H=1.5 m | C16: UN | D16: 47268
... B513: GRIFERIA ORINAL A PARED TIPO PUSH ENTRADA 1/2 CROMO DE CORONA | C513: UN | D513: 180249

Sheet EQUIPOS
B2: LISTADO DE EQUIPOS
B3: Insumo | C3: U.M. | D3: Vr.Unitario
B4: COMPRESOR 2 MARTILLOS COMPAIR C76 O SIMILAR | C4: DIA | D4: 640000
B5: EQUIPO DE PRECISIÓN TOPCON AT-B4 O SIMILAR | C5: DÌA | D5: 1320000
B6: FORMALETA DE ENTREPISO (M2 POR MES) | C6: DIA | D6: 5200
B7: HERRAMIENTA MENOR | C7: GL | D7: 1000
B8: MEZCLADORA 1 BT CON MOTOR A GASOLINA DE 9 HP O SIMILAR | C8: DIA | D8: 360000
B9: RETROEXCAVADORA KOMATSU WB-140 O SIMILAR | C9: DIA | D9: 760000
B10: VIBRADOR ELÉCTRICO M2000 O SIMILAR | C10: DÍA | D10: 33000
B11: VIBROCOMPACTADOR (RANA) 8 HP, 500 VIBRACIONES POR MINUTO | C11: DIA | D11: 304000

Sheet TRANSPORTE
B3: LISTADO DE TRANSPORTE
B4: Insumo | C4: U.M. | D4: Vr.Unitario
B5: VOLQUETA 6 M3 CON CARGUE | C5: HR | D5: 120000

Sheet MANO DE OBRA
B2: LISTADO DE MANO DE OBRA
B3: Insumo | C3: U.M. | D3: Vr.Unitario | E3: Vr. prestaciones | F3: Vr total | G3: Vr hora
B4: CUADRILLA ALB 0:2 | C4: DÍA | D4: 68945.4 | E4: =D4*12.5% -> 8618.175 | F4: =D4+E4 -> 77563.575 | G4: =F4/8 -> 9695.4469
B5: CUADRILLA ALB 1:1 | C5: DIA | D5: 85032.66 | E5: =D5*12.5% -> 10629.083 | F5: =D5+E5 -> 95661.743 | G5: =F5/8 -> 11957.718
B6: CUADRILLA TOP 1:2 | C6: DÍA | D6: 160872.6 | E6: =D6*12.5% -> 20109.075 | F6: =D6+E6 -> 180981.67 | G6: =F6/8 -> 22622.709
